<mujoco>
    <option gravity="0 0 -9.81"/>
    <worldbody>
        <light diffuse=".5 .5 .5" pos="0 0 3" dir="0 0 -1"/>
        <geom type="plane" size="5 5 0.1" rgba=".9 .9 .9 1"/>
        <body name="main" pos="0 0 1">
            <joint type="free"/>
            <geom type="sphere" size="0.2 0.2" rgba="0.486 0.917 0.97 0.75"/>  <!-- Changed shape to cylinder for spider body -->
            <site name="marker" pos="0 0 0" size="0.05"/>
            
            <!-- Define four spider legs -->
            <!-- red -->
            <body name="red-leg-upper-1" pos="0.4 0 0">
                <joint name="red-upper-joint-1" pos="-0.2 0 0" type="hinge" axis="0 1 0" range="-15 0"/>
                <geom type="cylinder" size="0.05 0.2" rgba="1 0 0 1" euler="0 90 0"/>
                <body name="red-upper-2" pos="0.4 0 0">
                    <joint name="red-upper-joint-2" pos="-0.2 0 0" type="hinge" axis="0 1 0" range="-15 0"/>
                    <geom type="cylinder" size="0.05 0.2" rgba="1 0 0 1" euler="0 90 0"/>
                    <body name="red-leg-lower-1" pos="0.2 0 -0.2">
                        <joint name="red-lower-joint-1" pos="0 0 0.2" type="hinge" axis="0 1 0" range="0 45"/>
                        <geom type="cylinder" size="0.04 0.2" pos="0 0 0" rgba="0.486 0.917 0.97 0.75"/>
                        <body name="red-lower-2" pos="0 0 -0.4">
                            <joint name="red-lower-joint-2" pos="0 0 0.2" type="hinge" axis="0 1 0" range="0 45"/>
                            <geom type="cylinder" size="0.04 0.2" pos="0 0 0" rgba="0.486 0.917 0.97 0.75"/>
                        </body>
                    </body>
                </body>
            </body>
            
            <!-- green -->
            <body name="green-leg-upper-1" pos="0 0.4 0">
                <joint name="green-upper-joint-1" pos="0 -0.2 0" type="hinge" axis="1 0 0" range="0 15"/>
                <geom type="cylinder" size="0.05 0.2" rgba="0 1 0 1" euler="90 0 0"/>
                <body name="green-upper-2" pos="0 0.4 0">
                    <joint name="green-upper-joint-2" pos="0 -0.2 0" type="hinge" axis="1 0 0" range="0 15"/>
                    <geom type="cylinder" size="0.05 0.2" rgba="0 1 0 1" euler="90 0 0"/>
                    <body name="green-leg-lower-1" pos="0 0.2 -0.2">
                        <joint name="green-lower-joint-1" pos="0 0 0.2" type="hinge" axis="1 0 0" range="-45 0"/>
                        <geom type="cylinder" size="0.04 0.2" pos="0 0 0" rgba="0.486 0.917 0.97 0.75"/>
                        <body name="green-lower-2" pos="0 0 -0.4">
                            <joint name="green-lower-joint-2" pos="0 0 0.2" type="hinge" axis="1 0 0" range="-45 0"/>
                            <geom type="cylinder" size="0.04 0.2" pos="0 0 0" rgba="0.486 0.917 0.97 0.75"/>
                        </body>
                    </body>
                </body>
            </body>
            
            <!-- blue -->
            <body name="blue-leg-upper-1" pos="-0.4 0 0">
                <joint name="blue-upper-joint-1" pos="0.2 0 0" type="hinge" axis="0 1 0" range="0 15"/>
                <geom type="cylinder" size="0.05 0.2" rgba="0 0 1 1" euler="0 -90 0"/>
                <body name="blue-upper-2" pos="-0.4 0 0">
                    <joint name="blue-upper-joint-2" pos="0.2 0 0" type="hinge" axis="0 1 0" range="0 15"/>
                    <geom type="cylinder" size="0.05 0.2" rgba="0 0 1 1" euler="0 -90 0"/>
                    <body name="blue-leg-lower-1" pos="-0.2 0 -0.2">
                        <joint name="blue-lower-joint-1" pos="0 0 0.2" type="hinge" axis="0 1 0" range="-45 0"/>
                        <geom type="cylinder" size="0.04 0.2" pos="0 0 0" rgba="0.486 0.917 0.97 0.75"/>
                        <body name="blue-lower-2" pos="0 0 -0.4">
                            <joint name="blue-lower-joint-2" pos="0 0 0.2" type="hinge" axis="0 1 0" range="-45 0"/>
                            <geom type="cylinder" size="0.04 0.2" pos="0 0 0" rgba="0.486 0.917 0.97 0.75"/>
                        </body>
                    </body>
                </body>
            </body>
            
            <!-- grey -->
            <body name="grey-leg-upper-1" pos="0 -0.4 0">
                <joint name="grey-upper-joint-1" pos="0 0.2 0" type="hinge" axis="1 0 0" range="-15 0"/>
                <geom type="cylinder" size="0.05 0.2" rgba="1 1 1 1" euler="-90 0 0"/>
                <body name="grey-upper-2" pos="0 -0.4 0">
                    <joint name="grey-upper-joint-2" pos="0 0.2 0" type="hinge" axis="1 0 0" range="-15 0"/>
                    <geom type="cylinder" size="0.05 0.2" rgba="1 1 1 1" euler="-90 0 0"/>
                    <body name="grey-leg-lower-1" pos="0 -0.2 -0.2">
                        <joint name="grey-lower-joint-1" pos="0 0 0.2" type="hinge" axis="1 0 0" range="-0 45"/>
                        <geom type="cylinder" size="0.04 0.2" pos="0 0 0" rgba="0.486 0.917 0.97 0.75"/>
                        <body name="grey-lower-2" pos="0 0 -0.4">
                            <joint name="grey-lower-joint-2" pos="0 0 0.2" type="hinge" axis="1 0 0" range="-0 45"/>
                            <geom type="cylinder" size="0.04 0.2" pos="0 0 0" rgba="0.486 0.917 0.97 0.75"/>
                        </body>
                    </body>
                </body>
            </body>
        </body>
    </worldbody>
    <sensor>
        <framepos objtype="site" objname="marker"/>
    </sensor>
    <actuator>
        <motor name="red-upper-motor-1" joint="red-upper-joint-1" />
        <motor name="red-upper-motor-2" joint="red-upper-joint-2" />
        <motor name="red-lower-motor-1" joint="red-lower-joint-1" />
        <motor name="red-lower-motor-2" joint="red-lower-joint-2" />
        <motor name="green-upper-motor-1" joint="green-upper-joint-1" />
        <motor name="green-upper-moto-2r" joint="green-upper-joint-2" />
        <motor name="green-lower-motor-1" joint="green-lower-joint-1" />
        <motor name="green-lower-motor-2" joint="green-lower-joint-2" />
        <motor name="blue-upper-motor-1" joint="blue-upper-joint-1" />
        <motor name="blue-upper-motor-2" joint="blue-upper-joint-2" />
        <motor name="blue-lower-motor-1" joint="blue-lower-joint-1" />
        <motor name="blue-lower-motor-2" joint="blue-lower-joint-2" />
        <motor name="grey-upper-motor-1" joint="grey-upper-joint-1" />
        <motor name="grey-upper-motor-2" joint="grey-upper-joint-2" />
        <motor name="grey-lower-motor-1" joint="grey-lower-joint-1" />
        <motor name="grey-lower-motor-2" joint="grey-lower-joint-2" />
    </actuator>
</mujoco>

